Workbook

Sheet Wunschliste
A1: Wunschliste
A2: Experimente | B2: Anzahl
A3: Michelson Interferometer | B3: 1
A4: Michelson + Piezo | B4: 1
A5: Mach-Zehnder-Interferometer | B5: 1
A6: Quantenradierer | B6: 1
A7: Gitter & Spalte | B7: 1
A8: Polarisation | B8: 1
A9: BB84 | B9: 0
A11: Extrawürfel
A12: Grundplatte 4x3 2St. | B12: 0
A13: Grundplatte 4x6 | B13: 0
A14: Strahlteiler | B14: 0
A15: Strahlteiler 44,2° | B15: 0
A16: Laser 3V | B16: 0
A17: LED-Würfel | B17: 0
A18: Batteriekasten | B18: 0
A19: Taster | B19: 0
A20: Laser 5V + USB | B20: 0
A21: Spiegel 90° | B21: 0
A22: Spiegel 90° - Piezo | B22: 0
A23: Spiegel 45° | B23: 0
... A33: BB84 Zufallswürfel | B33: 0

Sheet Bauteile nach Würfeln
A1: Bauteile | B1: Bezugsquelle | C1: Summe Module | D1: Grundplatte 4x3 2St. | E1: Grundplatte 4x6 | F1: Strahlteiler | G1: Strahlteiler 44,2° | H1: Laser 3V | I1: LED-Würfel | J1: Batteriekasten | K1: Taster | L1: Laser 5V + USB | M1: Spiegel 90° | N1: Spiegel 90° - Piezo | O1: Spiegel 45° | P1: Linse 15mm | Q1: Linse 26,5mm | R1: Linse 65mm | S1: Polfilter | T1: Gitterhalter | U1: Schirm | V1: Zielhilfe | W1: Paar Basispolfilter | X1: Gekoppelter Polfilter | Y1: BB84 Zufallswürfel
A2: Benötigt für ausgewählte Sets | C2: =SUM(L2:W2) -> 18 | D2: {=MAX(D102:D108*$C102:$C108)+SUM(D110:D130*$C110:$C130)} -> 1 | E2: {=MAX(E102:E108*$C102:$C108)+SUM(E110:E130*$C110:$C130)} -> 0 | F2: {=MAX(F102:F108*$C102:$C108)+SUM(F110:F130*$C110:$C130)} -> 2 | G2: {=MAX(G102:G108*$C102:$C108)+SUM(G110:G130*$C110:$C130)} -> 0 | H2: {=MAX(H102:H108*$C102:$C108)+SUM(H110:H130*$C110:$C130)} -> 1 | I2: {=MAX(I102:I108*$C102:$C108)+SUM(I110:I130*$C110:$C130)} -> 1 | J2: {=MAX(J102:J108*$C102:$C108)+SUM(J110:J130*$C110:$C130)} -> 1 | K2: {=MAX(K102:K108*$C102:$C108)+SUM(K110:K130*$C110:$C130)} -> 0 | ... X2: {=MAX(X102:X108*$C102:$C108)+SUM(X110:X130*$C110:$C130)} -> 0 | Y2: {=MAX(Y102:Y108*$C102:$C108)+SUM(Y110:Y131*$C110:$C131)} -> 0
A3: 00A_Sw_V1_Grundplatte 4x6 | B3: https://o3q.de/anleitungen-dateien/ | C3: =SUMPRODUCT(D3:Y3,D$2:Y$2) -> 0 | D3: 0 | E3: 1
A4: 00B_Sw_V2_Grundplatte_Verb. 4x3 | B4: https://o3q.de/anleitungen-dateien/ | C4: =SUMPRODUCT(D4:Y4,D$2:Y$2) -> 2 | D4: 2
A5: 00B_Sw_V2_Verbinder_Gr.P | B5: https://o3q.de/anleitungen-dateien/ | C5: =SUMPRODUCT(D5:Y5,D$2:Y$2) -> 3 | D5: 3
A6: 01A_Go_V1_Würfelboden 1x1 | B6: https://o3q.de/anleitungen-dateien/ | C6: =SUMPRODUCT(D6:Y6,D$2:Y$2) -> 18 | F6: 1 | G6: 1 | H6: 1 | I6: 1 | L6: 1 | M6: 1 | N6: 1 | O6: 1 | P6: 1 | Q6: 1 | R6: 1 | S6: 1
A7: 01B_Go_V1_Würfelboden 1x1_geschlossen | B7: https://o3q.de/anleitungen-dateien/ | C7: =SUMPRODUCT(D7:Y7,D$2:Y$2) -> 1 | K7: 1 | T7: 1
A8: 01C_Go_V1_Würfelboden 1x2 | B8: https://o3q.de/anleitungen-dateien/ | C8: =SUMPRODUCT(D8:Y8,D$2:Y$2) -> 0 | X8: 1
A9: 01D_Go_V1_Batteriekasten_Boden | B9: https://o3q.de/anleitungen-dateien/ | C9: =SUMPRODUCT(D9:Y9,D$2:Y$2) -> 1 | J9: 1
A10: 01E_Go_V1_Basispolfilter_Boden | B10: https://o3q.de/anleitungen-dateien/ | C10: =SUMPRODUCT(D10:Y10,D$2:Y$2) -> 0 | W10: 4
A11: 07A_Go_V1_Basiswürfel | B11: https://o3q.de/anleitungen-dateien/ | C11: =SUMPRODUCT(D11:Y11,D$2:Y$2) -> 0 | Y11: 2
A12: 07B_Go_V1_Bitwürfel | B12: https://o3q.de/anleitungen-dateien/ | C12: =SUMPRODUCT(D12:Y12,D$2:Y$2) -> 0 | Y12: 2
A13: 02A_Br_V1_Würfeldeckel 1x1 | B13: https://o3q.de/anleitungen-dateien/ | C13: =SUMPRODUCT(D13:Y13,D$2:Y$2) -> 18 | F13: 1 | G13: 1 | H13: 1 | I13: 1 | L13: 1 | M13: 1 | N13: 1 | O13: 1 | P13: 1 | Q13: 1 | R13: 1 | S13: 1
A14: 02B_V1_Würfeldeckel 1x1_Taster | B14: https://o3q.de/anleitungen-dateien/ | C14: =SUMPRODUCT(D14:Y14,D$2:Y$2) -> 0 | K14: 1
A15: 02C_Br_V1_Würfeldeckel 1x2 | B15: https://o3q.de/anleitungen-dateien/ | C15: =SUMPRODUCT(D15:Y15,D$2:Y$2) -> 0 | X15: 1
A16: 02D_Br_V1_Batteriekasten_Deckel | B16: https://o3q.de/anleitungen-dateien/ | C16: =SUMPRODUCT(D16:Y16,D$2:Y$2) -> 1 | J16: 1
A17: 05A_Si_V1_Gitterhalter_Rahmen | B17: https://o3q.de/anleitungen-dateien/ | C17: =SUMPRODUCT(D17:Y17,D$2:Y$2) -> 1 | T17: 1
A18: 05A_Si_V1_Gitterhalter_Stopper | B18: https://o3q.de/anleitungen-dateien/ | C18: =SUMPRODUCT(D18:Y18,D$2:Y$2) -> 1 | T18: 1
A19: 05A_Si_V1_Gitterhalter_Schlitten | B19: https://o3q.de/anleitungen-dateien/ | C19: =SUMPRODUCT(D19:Y19,D$2:Y$2) -> 1 | T19: 1
A20: 06A_Si_V1_Basispolfilter_Filterabdeckung | B20: https://o3q.de/anleitungen-dateien/ | C20: =SUMPRODUCT(D20:Y20,D$2:Y$2) -> 0 | W20: 2
A21: 06B_Si_+Basispolfilter_Mitte | B21: https://o3q.de/anleitungen-dateien/ | C21: =SUMPRODUCT(D21:Y21,D$2:Y$2) -> 0 | W21: 1
A22: 06C_Si_xBasispolfilter_Mitte | B22: https://o3q.de/anleitungen-dateien/ | C22: =SUMPRODUCT(D22:Y22,D$2:Y$2) -> 0 | W22: 1
A23: 10A_Si_V1_Einsatz 90° | B23: https://o3q.de/anleitungen-dateien/ | C23: =SUMPRODUCT(D23:Y23,D$2:Y$2) -> 5 | H23: 1 | I23: 1 | L23: 1 | M23: 1 | N23: 1
A24: 10B_Si_V1_Einsatz 45° | B24: https://o3q.de/anleitungen-dateien/ | C24: =SUMPRODUCT(D24:Y24,D$2:Y$2) -> 3 | O24: 1
A25: 11A_Si_V1_Laserplatte | B25: https://o3q.de/anleitungen-dateien/ | C25: =SUMPRODUCT(D25:Y25,D$2:Y$2) -> 1 | H25: 1 | L25: 1
A26: 11A_Si_V1_Laser_Zugentlastung | B26: https://o3q.de/anleitungen-dateien/ | C26: =SUMPRODUCT(D26:Y26,D$2:Y$2) -> 1 | H26: 1 | L26: 1
A27: 11B_Si_V1_LEDplatte | B27: https://o3q.de/anleitungen-dateien/ | C27: =SUMPRODUCT(D27:Y27,D$2:Y$2) -> 1 | I27: 1
A28: 11C_Si_V1_Spiegelplatte | B28: https://o3q.de/anleitungen-dateien/ | C28: =SUMPRODUCT(D28:Y28,D$2:Y$2) -> 5 | M28: 1 | O28: 1
A29: 11D_Si_V1_Spiegelplatte_Piezo | B29: https://o3q.de/anleitungen-dateien/ | C29: =SUMPRODUCT(D29:Y29,D$2:Y$2) -> 1 | N29: 1
A30: 12A_Si_V1_Strahlteiler_Oben | B30: https://o3q.de/anleitungen-dateien/ | C30: =SUMPRODUCT(D30:Y30,D$2:Y$2) -> 2 | F30: 1 | G30: 1
A31: 12A_Si_V1_Strahlteiler_Klemme | B31: https://o3q.de/anleitungen-dateien/ | C31: =SUMPRODUCT(D31:Y31,D$2:Y$2) -> 2 | F31: 1
A32: 12A_Si_V1_Strahlteiler_Unten | B32: https://o3q.de/anleitungen-dateien/ | C32: =SUMPRODUCT(D32:Y32,D$2:Y$2) -> 2 | F32: 1
A33: 12B_Si_V3_Strahlteiler_Klemme 42,2° | B33: https://o3q.de/anleitungen-dateien/ | C33: =SUMPRODUCT(D33:Y33,D$2:Y$2) -> 0 | G33: 1
A34: 12B_Si_V3_Strahlteiler_Unten 42,2° | B34: https://o3q.de/anleitungen-dateien/ | C34: =SUMPRODUCT(D34:Y34,D$2:Y$2) -> 0 | G34: 1
A35: 13A_Si_V0_Linsenhalter | B35: https://o3q.de/anleitungen-dateien/ | C35: =SUMPRODUCT(D35:Y35,D$2:Y$2) -> 0
A36: 13B_Si_V1_Linsenhalter_f=15mm | B36: https://o3q.de/anleitungen-dateien/ | C36: =SUMPRODUCT(D36:Y36,D$2:Y$2) -> 1 | P36: 1
A37: 13C_Si_V1_Linsenhalter_f=26,5mm | B37: https://o3q.de/anleitungen-dateien/ | C37: =SUMPRODUCT(D37:Y37,D$2:Y$2) -> 1 | Q37: 1
A38: 13D_Si_V1_Linsenhalter_f=65mm | B38: https://o3q.de/anleitungen-dateien/ | C38: =SUMPRODUCT(D38:Y38,D$2:Y$2) -> 1 | R38: 1
A39: 14A_Si_V1_Polfilter_Halteplatte | B39: https://o3q.de/anleitungen-dateien/ | C39: =SUMPRODUCT(D39:Y39,D$2:Y$2) -> 5 | S39: 1
A40: 14A_Si_V1_Polfilter_Zwischenplatte | B40: https://o3q.de/anleitungen-dateien/ | C40: =SUMPRODUCT(D40:Y40,D$2:Y$2) -> 5 | S40: 1
...
